Workbook

Sheet Indice
A1: HOJA | B1: CONTENIDO | C1: FILAS
A2: Requisitos | B2: Requisitos aplicables a la tarjeta de OBC + COMMS (PCB 2) | C2: 12
A3: Especificaciones | B3: Especificaciones técnicas de la tarjeta COMMS+OBC | C3: 37
A4: Funciones | B4: Funciones de hardware y software asignadas a la tarjeta OBC + COMMS | C4: 9
A5: Restricciones PCB | B5: Restricciones para el diseño PCB OBC + COMMS | C5: 8
A6: DFM fabricante | B6: Parámetros de diseño DFM vs. límites de fabricación de PCBWay | C6: 13
A7: Restricciones Altium | B7: Matriz de restricciones del proyecto Altium y criterio de comprobación. | C7: 12
A8: Plan verificacion | B8: Plan de verificación y trazabilidad preliminar. | C8: 12
A9: Registro incidencias | B9: Registro de incidencias y evidencias de verificación (por completar con resultados reales). | C9: 2
A10: Inventario componentes | B10: Referencias principales del inventario actualizado; cantidades y montaje por confirmar en Altium. | C10: 24
A11: Resumen costos | B11: Resumen costos | C11: 3

Sheet Requisitos
A1: ID | B1: Tipo | C1: Requisito | D1: Origen o justificación | E1: Prioridad | F1: Criterio de aceptación
A2: RF-02 | B2: Funcional | C2: El CubeSat deberá almacenar temporalmente los datos generados por la carga útil antes de su transmisión a tierra. | D2: S-05 / Operación de la carga útil. | E2: Alta | F2: La capacidad de almacenamiento definida en la eMMC/MRAM de la PCB deberá ser igual o superior al volumen máximo de datos generado entre oportunidades de descarga.
A3: RF-03 | B3: Funcional | C3: El CubeSat deberá transmitir a la estación terrestre los datos de misión y la telemetría correspondiente al estado del satélite. | D3: S-08 / Comunicación satélite–tierra. | E3: Alta | F3: El presupuesto de enlace de la etapa RF de la tarjeta deberá demostrar la capacidad de realizar el enlace descendente durante una ventana de comunicación prevista.
A4: RF-04 | B4: Funcional | C4: El CubeSat deberá recibir comandos provenientes de la estación terrestre. | D4: S-08 / Comunicación bidireccional. | E4: Alta | F4: La arquitectura de comunicaciones en la PCB deberá contemplar un enlace ascendente (UHF) capaz de recibir y entregar comandos al sistema de manejo de datos.
A5: RNF-01 | B5: No funcional | C5: La plataforma espacial deberá ser capaz de operar nominalmente en órbita baja terrestre durante un período mínimo de seis (6) meses sin degradación crítica de sus funciones. | D5: S-02 / Duración nominal de la misión. | E5: Alta | F5: La selección y análisis de los componentes activos y pasivos de la PCB deberá demostrar compatibilidad con una duración mínima de misión de seis meses en el ambiente orbital considerado.
A6: RNF-03 | B6: No funcional | C6: El sistema de comunicaciones deberá proporcionar un enlace con margen positivo bajo las condiciones nominales de comunicación con la estación terrestre de referencia. | D6: S-04 y S-08 / Enlace de comunicaciones. | E6: Alta | F6: El presupuesto de enlace de las etapas UHF y Banda S integradas en la PCB deberá presentar un margen superior a 0 dB para las condiciones nominales adoptadas.
A7: RNF-04 | B7: No funcional | C7: Los subsistemas eléctricos deberán utilizar interfaces de alimentación y datos compatibles entre sí. | D7: Integración del sistema. | E7: Alta | F7: La etapa de regulación local (POL) y los buses de datos de la PCB deberán demostrar compatibilidad de tensión, corriente, niveles eléctricos y protocolos con el resto de subsistemas.
A8: RA-01 | B8: Ambiental | C8: El hardware del CubeSat deberá ser compatible con la operación en vacío durante la fase orbital de la misión. | D8: S-03 / Ambiente espacial de operación. | E8: Alta | F8: Los componentes, conectores y materiales de la PCB (sustrato híbrido) deberán disponer de características documentadas compatibles con la operación en vacío.
A9: RA-02 | B9: Ambiental | C9: El CubeSat deberá soportar el entorno térmico asociado con los ciclos de iluminación y eclipse de la órbita definida para la misión. | D9: S-03 / Entorno térmico orbital. | E9: Alta | F9: El análisis térmico de la tarjeta deberá demostrar que las temperaturas estimadas de los integrados (SoC, PAs de RF, memorias) permanecen dentro de sus límites admisibles.
A10: RA-03 | B10: Ambiental | C10: La estructura y los componentes del CubeSat deberán permanecer mecánicamente íntegros frente a las cargas previstas durante el lanzamiento y despliegue. | D10: Entorno de lanzamiento / Seguridad. | E10: Alta | F10: La verificación estructural de la PCB deberá demostrar la integridad de los encapsulados BGA, TSOP, conectores PC/104 y uniones de soldadura frente a los niveles de vibración adoptados.
A11: RA-04 | B11: Ambiental | C11: Los equipos electrónicos críticos del CubeSat deberán mantener su funcionalidad después de una Dosis Ionizante Total de diseño de al menos 5 krad(Si). | D11: S-02 y S-03 / Entorno de radiación correspondiente a una misión de seis meses en SSO a 550 km. | E11: Alta | F11: La tolerancia documentada a TID de los integrados críticos de la PCB (SmartFusion2, MRAM, eMMC, RFICs) deberá ser igual o superior al valor de diseño determinado.
A12: RA-05 | B12: Ambiental | C12: Los componentes electrónicos críticos susceptibles a latch-up deberán presentar un umbral de susceptibilidad a SEL por iones pesados igual o superior a 60 MeV cm^2/mg. | D12: S-03 / ECSS-E-ST-10-12C, entorno de radiación y efectos de evento único. | E12: Alta | F12: Verificar documentalmente o mediante circuitos de protección local (*Load Switches*) que los componentes de la PCB susceptibles a SEL presenten LET_th 60 MeV cm^2/mg.
A13: RN-04 | B13: Normativo | C13: El subsistema de comunicaciones deberá operar dentro de bandas y condiciones de emisión compatibles con la reglamentación de espectro aplicable a la misión. | D13: S-08 / Regulación de comunicaciones satelitales. | E13: Alta | F13: Las etapas de transmisión UHF y Banda S de la PCB deberán ajustarse a la asignación de frecuencias, anchos de banda y potencias de emisión autorizadas.

Sheet Especificaciones
A1: ID de especificación | B1: Requisitos asociados | C1: Parámetro técnico | D1: Valor, rango o tolerancia | E1: Unidad | F1: Fundamento | G1: Método previsto de verificación
A2: ET-MIS-01 | B2: RNF-01 | C2: Vida útil nominal de la misión | D2: 6 | E2: meses | F2: Duración mínima establecida en el supuesto S-02. Condiciona la selección de componentes de la tarjeta. | G2: A, I
A3: ET-ORB-01 | B3: RA-02, RA-04 | C3: Altitud orbital de referencia | D3: 550 nominal | E3: km | F3: Órbita adoptada en el supuesto S-03. Se usa en el presupuesto de enlace y en el análisis de radiación de la tarjeta. | G3: A
A4: ET-GS-01 | B4: RNF-03 | C4: Estación terrestre de referencia | D4: Medellín | E4: – | F4: Ubicación definida en el supuesto S-04. Base del presupuesto de enlace de las bandas UHF y S. | G4: A
A5: ET-OBC-01 | B5: RF-02 | C5: Elemento de procesamiento | D5: Microchip M2S050-FGG484I (ARM + FPGA) | E5: – | F5: Se requiere lógica programable para implementar el host eMMC y la codificación Reed-Solomon del enlace UHF, además del procesador de a bordo. | G5: I
A6: ET-OBC-02 | B6: RF-02 | C6: Frecuencia del reloj del sistema | D6: 50 | E6: MHz | F6: Oscilador Aker S3A33025 alimentado a 3.3 V. | G6: I
A7: ET-OBC-03 | B7: RNF-01 | C7: Supervisión de alimentación y watchdog | D7: Supervisor de 3.3 V con watchdod | E7: – | F7: Texas Instruments TPS3823-33-EP. Reinicia el sistema ante caídas de tensión o bloqueo del software. | G7: A, I, D
A8: ET-MEM-01 | B8: RF-02 | C8: Memoria RAM de trabajo | D8: 512 (4 Gb) | E8: MB | F8: ISSI IS43TR16256A-125KBLI (DDR3L, 1.35 V). Capacidad deducida de la organización 256M 16; | G8: A, I
A9: ET-MEM-02 | B9: RF-02 | C9: Memoria no volátil para firmware | D9: 2 por dispositivo, de 2 a 4 dispositivos | E9: MB | F9: Everspin MR4A16BCYS35 en TSOP2-54. La cantidad de unidades depende de la redundancia de firmware que se adopte. | G9: A, I
A10: ET-MEM-03 | B10: RF-02 | C10: Capacidad nominal de almacenamiento masivo | D10: 32 | E10: GB | F10: Micron MTFC32GAPALBH-AAT (eMMC). El host se implementa en la fabric del SoC. La capacidad útil se verifica contra ET-DAT-02. | G10: A, I
A11: ET-DAT-01 | B11: RF-01, RF-02 | C11: Volumen de datos por adquisición | D11: 21 | E11: MB | F11: Se calculará a partir de la resolución del sensor, número de bandas, profundidad de bits y esquema de compresión adoptado. Dimensiona el almacenamiento de la tarjeta. | G11: A
A12: ET-DAT-02 | B12: RF-02 | C12: Capacidad útil mínima de almacenamiento masivo | D12: 8 | E12: GB | F12: Se calculará a partir del máximo volumen de datos acumulado entre oportunidades consecutivas de descarga, y se comparará con ET-MEM-03. | G12: A, I
... A28: ET-INT-04 | B28: RNF-04 | C28: Conector de programación y depuración | D28: 10 | E28: pines | F28: Samtec HTST10501-LDVDA. Acceso al SoC para programación y depuración. | G28: I, D
A29: ET-INT-05 | B29: RF-03, RNF-04 | C29: Conectores de antena | D29: 2 SMP (UHF y banda S), 50 | F29: Rosenberger 18S142-40ML5. La impedancia de 50 es una inferencia por confirmar con la hoja de datos. | G29: I, T
A30: ET-MEC-01 | B30: RN-01 | C30: Configuración mecánica | D30: 1U | E30: – | F30: Formato definido por S-01 y la CubeSat Design Specification Rev. 14.1. Acota el área disponible de la tarjeta. | G30: I
A31: ET-PCB-01 | B31: RF-03, RF-04 | C31: Material del apilamiento de la PCB | D31: Rogers RO4350B + Isola 370HR; 8 Capas | E31: – | F31: Material de bajas pérdidas para las capas de RF y material estándar para el resto. El apilamiento se detalla en la guía de enrutamiento. | G31: A, I
A32: ET-PCB-02 | B32: RF-03, RF-04 | C32: Blindaje contra interferencia electromagnética | D32: Blindaje Harwin sobre las secciones de RF; referencia TBD | E32: – | F32: Separa los circuitos de RF de los circuitos digitales y de potencia de la tarjeta. | G32: A, I
A33: ET-ENV-01 | B33: RA-01 | C33: Ambiente de operación durante la fase orbital | D33: Vacío orbital | E33: – | F33: Condición ambiental derivada de la operación en órbita definida en S-03. | G33: A, I
A34: ET-TH-01 | B34: RA-02 | C34: Rango térmico de diseño | D34: -20 a 85 | E34: ^C | F34: Se determinará mediante análisis térmico. La MRAM (-40 a +85 ^C) y el conmutador PE4259 (máximo 85 ^C) fijan el límite superior. | G34: A
A35: ET-STR-01 | B35: RA-03 | C35: Nivel de cargas y vibraciones de lanzamiento | D35: 14.1 | E35: Grms | F35: Perfil de vibración aleatoria envolvente (NASA GEVS GSFC-STD-7000A) y cargas cuasi-estáticas para la verificación de encapsulados BGA, TSOP y conectores de la tarjeta. | G35: A, T
A36: ET-RAD-01 | B36: RA-04 | C36: Dosis Ionizante Total de diseño | D36: 5 | E36: krad(Si) | F36: Dosis ionizante acumulada calculada para 6 meses en SSO a 550 km, considerando blindaje equivalente de 1.5 mm de aluminio y un margen de diseño RDM de 2.5x. | G36: A
A37: ET-RAD-02 | B37: RA-05 | C37: Umbral mínimo de susceptibilidad a SEL | D37: 60 | E37: MeV cm^2mg | F37: Valor establecido en RA-05 para los componentes críticos de la tarjeta susceptibles a Single Event Latch-up. | G37: I
A38: ET-RAD-03 | B38: RA-04 | C38: Mitigación de errores en memoria | D38: SECDED en la DDR3L; firmware replicado en 2 a 4 MRAM | E38: – | F38: Los controladores DDR del SoC admiten SECDED. La redundancia de MRAM protege el firmware frente a errores por radiación. | G38: A, D

Sheet Funciones
A1: Función | B1: Tipo de implementación | C1: Recursos de hardware necesarios | D1: Responsabilidad del software futuro | E1: Justificación
A2: Procesamiento de datos de la carga útil | B2: Software | C2: Procesador dedicado/SoC (SmartFusion2 con matriz FPGA y núcleo ARM), RAM DDR3L y almacenamiento masivo local. | D2: Gestionar los datos adquiridos, generar metadatos, verificar integridad y realizar operaciones de preparación o compresión antes del almacenamiento o transmisión. | E2: La función es principalmente algorítmica. La FPGA y el procesador de la PCB 2 constituyen el recurso físico sobre el cual se ejecuta el software de procesamiento.
A3: Almacenamiento de imágenes | B3: Mixta | C3: Memoria no volátil (eMMC / NAND Flash de 8–32 GB) con interfaz compatible montada en la tarjeta central. | D3: Administrar archivos o bloques de datos, controlar la ocupación, verificar integridad mediante CRC y eliminar los datos descargados correctamente. | E3: RF-02. La memoria masiva local realiza físicamente el almacenamiento, mientras que el software administra la organización e integridad de la información.
A4: Buffer temporal de imágenes | B4: Software | C4: Memoria RAM disponible mínima de 16 MB en la cadena de procesamiento de la tarjeta. | D4: Gestionar buffers de entrada y salida, controlar transferencias entre la cámara, RAM y memoria no volátil y evitar pérdida de información. | E4: La función corresponde principalmente a gestión de memoria de trabajo para manipular los paquetes de imagen antes de su compresión o guardado.
A5: Control y coordinación central del CubeSat | B5: Software | C5: Computador de a bordo basado en SoC ARM Cortex-M3, memoria no volátil y buses CAN, SPI, UART, I^2C y LVDS. | D5: Ejecutar la máquina de estados de misión, coordinar subsistemas, gestionar modos de operación, procesar eventos y ejecutar las acciones asociadas a los comandos recibidos. | E5: La coordinación del sistema depende principalmente de la lógica del software de vuelo; el hardware del OBC proporciona los recursos computacionales necesarios.
A6: Temporización y referencia temporal | B6: Mixta | C6: RTC, oscilador de referencia (TCXO) y temporizadores disponibles en el computador de a bordo. | D6: Mantener el tiempo de misión, generar marcas temporales para imágenes y telemetría y programar eventos de operación. | E6: El hardware de la tarjeta proporciona la referencia temporal estable y el software la utiliza para sincronizar los eventos de misión.
A7: Detección y recuperación ante fallos | B7: Mixta | C7: Watchdog hardware externo, supervisores de alimentación locales y limitadores de corriente (Load Switches). | D7: Detectar condiciones anómalas, registrar eventos, reiniciar subsistemas y llevar el satélite a un estado seguro cuando sea necesario. | E7: Combina mecanismos autónomos de protección en hardware local con estrategias de detección y recuperación implementadas mediante software.
A8: Recepción de comandos críticos | B8: Mixta | C8: Transceptor UHF (AX5043 / CC1120 o equivalente) en el rango de 400 MHz con tasa nominal de 9.6 kbps. | D8: Validar la integridad de las tramas recibidas, interpretar los comandos y generar las acciones correspondientes sobre los subsistemas. | E8: RF-04. El transceptor realiza la recepción física en radiofrecuencia, mientras que el software interpreta y ejecuta el contenido del comando.
A9: Transmisión de telemetría | B9: Mixta | C9: Transceptor UHF con tasa nominal de 9.6 kbps y conexión digital directa con el procesador central. | D9: Construir paquetes de housekeeping con tensiones, corrientes, temperaturas, estados, alarmas y eventos, y gestionar su envío. | E9: RF-03. El software genera y organiza la telemetría mientras el hardware de radiofrecuencia realiza el enlace físico descendente.
A10: Transmisión de imágenes | B10: Mixta | C10: Transmisor de alta velocidad en Banda S (2.2–2.4 GHz) con capacidad de 1 Mbps a 8 Mbps. | D10: Fragmentar las imágenes, organizar los paquetes, gestionar la cola de transmisión y mantener registro de la información descargada. | E10: RF-03. El software gestiona el flujo de paquetes desde la eMMC hacia la etapa RF de Banda S para su descarga durante la ventana sobre Medellín.

Sheet Restricciones PCB
A1: ID y Trazabilidad | B1: Restricción y Alcance | C1: Fuente y Fundamento | D1: Aplicación y Verificación
A2: PCB-01 (RF-03, RN-04) | B2: Apilamiento Híbrido (Stackup): Placa de 8 a 12 capas. Capas externas (Top/Bottom) en Rogers RO4350B (alta frecuencia) y capas internas en FR-4 High-Tg / Isola 370HR para lógica digital. | C2: Recomendación de arquitectura RF/Digital: El FR-4 estándar presenta pérdidas inaceptables en Banda S (2.4 GHz). El stackup híbrido optimiza costos e integridad de señal. | D2: Directiva de fabricación: Supuesto preliminar para el fabricante de PCBs. Verificación en el Layer Stack Manager del CAD.
A3: PCB-02 (RA-01, RA-02) | B3: Disipación Térmica (Vías): Arreglos de vías térmicas (thermal vias) bajo los PAs de RF (ADL5324) y el SoC SmartFusion2, conectando a planos gruesos de cobre (2 oz) vinculados al chasis. | C3: Inferencia justificada (Entorno Espacial): En el vacío no existe convección. Los integrados de alto consumo colapsarán térmicamente sin conducción directa a la estructura. | D3: Regla de layout: Colocación de polígonos térmicos y matrices de vías. Verificación mediante análisis térmico del CAD y revisión visual.
A4: PCB-03 (RNF-03, RF-03) | B4: Impedancia Controlada RF y Aislamiento: Microcintas Coplanares con Plano de Masa (CPWG) a 50 hacia conectores SMP, rodeadas por apantallamiento de vías (via fencing). | C4: Datasheet SMP y RFICs: Evita pérdidas por desacople, ondas reflejadas y radiación que degraden la figura de ruido o dañen las etapas de salida. | D4: Directiva de ruteo: El ancho de pista dependerá del stackup final. Verificación por calculadora de impedancia y regla DRC en el CAD.
A5: PCB-04 (RNF-04, IF-02, IF-07) | B5: Integridad de Señales Diferenciales (LVDS): Enlaces LVDS/MIPI con impedancia diferencial de 100 . Acoplamiento de longitud (desfase <0.3 mm) y plano de masa continuo adyacente. | C5: Estándar LVDS / ECSS SpaceWire: Cancela el ruido de modo común, minimiza emisiones EMI y previene desalineación de fase a altas velocidades. | D5: Regla DRC de alta velocidad: Differential Pairs Routing y Length Tuning (Meandering). Verificación automática en el DRC.
A6: PCB-05 (RNF-03, EMC) | B6: Apantallamiento Electromagnético (EMI): Cajas de blindaje SMD independientes (Shielding Cans) para las secciones UHF, Banda S y reguladores Buck conmutados. | C6: Buena práctica RF (Aislamiento): El ruido digital del SoC y la emisión UHF (1 W) pueden ensordecer los receptores LNA o acoplar ruido al enlace de Banda S. | D6: Regla de layout: Footprints para clips de blindaje y zonas keep-out sin pistas en la capa top. Revisión de modelo 3D.
A7: PCB-06 (RNF-04, POL(Point of Load)) | B7: Ubicación de Regulación RF (LDOs): LDOs de ultra-bajo ruido (LT3042/LT3045) ubicados a milímetros de las entradas analógicas del AD9364 (1.3 V) y LNAs. | C7: Datasheet AD9364 y LNAs: Los PLLs y sintetizadores son sensibles al rizado de tensión. Separarlos de reguladores conmutados asegura un PSRR óptimo. | D7: Directiva de placement: Aislamiento de dominios de energía en la hoja POL y ruteo directo. Revisión manual del esquemático.
A8: PCB-07 (OBC, Power) | B8: Desacoplamiento SoC y Filtrado LC: Múltiples capacitores en paralelo pegados al BGA (1.2 V). Filtrado pasivo LC (ferrita + cap) exclusivo para las líneas VDD_PLL. | C8: Guía de aplicación SmartFusion2: Inductores en el núcleo provocan caídas por dI/dt. Los PLLs requieren filtrado pasivo al consumir corriente estable. | D8: Restricción de ruteo: Capacitores colocados en la misma capa del BGA o con vías cortas directas. Verificación visual 3D e inspección de ERC.
A9: PCB-08 (RNF-02, EPS) | B9: Control de Pico de Corriente (Soft-Start): Capacitores de 3.3 nF a 10 nF en el pin SS/TR de los Bucks TPS62130A para un arranque suave de 2-4 ms. | C9: Datasheet TPS62130A y dinámica sistémica: Previene colapsos en el bus de alimentación global del EPS al cargar el banco de capacitores del SoC/DDR3L. | D9: Comprobación esquemática (ERC): Verificación de selección de dieléctricos C0G/X7R en la BOM y simulación de tiempo de arranque.

Sheet DFM fabricante
A1: Parámetro DFM | B1: Parámetro Escogido (PCB 2) | C1: Límite del Fabricante (PCBWay) | D1: Fundamento / Criterio de Selección
A2: Número de capas | B2: 8 capas | C2: Hasta 64 capas | D2: Requerido para el escape (*fanout*) del BGA de 484 pines (SmartFusion2), ruteo de buses LVDS y planos de masa para RF.
A3: Material base y Stackup | B3: Híbrido: Rogers RO4350B (capas ext.) + FR-4 High-Tg / Isola 370HR (capas int.) | C3: FR-4 High-Tg (Tg170–220), Rogers 4350/4003, PTFE, Cerámico, Prensado mixto (2–20 capas) | D3: Minimiza la atenuación dieléctrica en la etapa de Banda S (2.4 GHz) en capas externas y optimiza costos en capas digitales internas.
A4: Espesor nominal de la placa | B4: 1.6 mm 7% | C4: 0.21 mm - 6.0 mm ( 7% para espesores entre 1.0 mm y 2.5 mm) | D4: Estándar mecánico compatible con los conectores apilables PC/104 de la estructura CubeSat 1U y rigidez ante vibraciones.
A5: Ancho de pista y espaciamiento (W/S) | B5: 4.0 mil / 4.0 mil (0.10 mm) | C5: Mínimo 2.0 mil / 2.0 mil (0.05 mm) en capas internas y externas | D5: Facilita el ruteo entre los pines del BGA (0.8 mm pitch) manteniendo un alto rendimiento de fabricación (*yield*).
A6: Diámetro de perforación vía (Drill) | B6: 0.20 mm (8 mil) mecánico pasante | C6: Mínimo 0.15 mm (Mecanizado CNC) / 0.10 mm (Microvía Láser ciega/enterrada) | D6: Permite la transición entre capas sin recurrir a microvías láser de alto costo (tecnología HDI estándar pasante).
A7: Relación de aspecto (*Aspect Ratio*) | B7: 8:1 (1.6 mm / 0.20 mm) | C7: Hasta 12:1 (estándar) / 20:1 (capacidad máxima) | D7: Garantiza la homogeneidad y continuidad del cobreado electrolítico en las paredes internas de las vías pasantes.
A8: Anillo de cobre (*Annular Ring*) | B8: 4.0 mil (0.10 mm) en vías / 6.0 mil en orificios THT | C8: Mínimo 3.0 mil en vías / 5.0 mil en orificios de componentes | D8: Previene la desalineación de la perforación (*breakout*) y asegura la integridad bajo delaminación por ciclos térmicos.
A9: Capacidad para componentes BGA | B9: Pitch de 0.8 mm / Pad de 0.35 mm | C9: Pitch mínimo de BGA: 0.4 mm / Diámetro mínimo de BGA: 8 mil (0.20 mm) | D9: Adaptado a la matriz FGG484 del SoC SmartFusion2 (M2S050) y chips de memoria masiva.
A10: Puente de máscara de soldadura (*Solder Mask Dam*) | B10: 4.0 mil (0.10 mm) | C10: Mínimo 3.0 mil (máscara verde) / 4.0 mil (máscara negra/otras) | D10: Retiene el flujo de soldadura entre pads adyacentes de alta densidad para prevenir cortocircuitos por puentes durante el *reflow*.
A11: Acabado superficial (*Surface Finish*) | B11: **ENIG** (*Electroless Nickel Immersion Gold*) | C11: ENIG, HASL, Lead Free HASL, OSP, Immersion Ag/Sn, Plating Hard Gold | D11: Superficie plana indispensable para encapsulados BGA/QFN de paso fino y excelente resistencia a la oxidación en almacenamiento/vacío.
A12: Tolerancia de control de impedancia | B12: 10% (50 RF CPWG / 100 diferencial LVDS) | C12: 10% ( 5 para impedancias 50 ) | D12: Asegura la integridad de señal en la interfaz del SDR AD9364, conector SMP y las trazas de alta velocidad de la cámara.
... A14: Espesor del cobre (*Copper Thickness*) | B14: Capas ext.: 1.0 oz (35 ) / Capas int.: 0.5 - 1.0 oz | C14: Cobre base mín. 1/3 oz (12 ) hasta 8 oz máximo final | D14: Proporciona la capacidad de conducción necesaria para los reguladores POL y estabilidad para el grabado de líneas de RF.

Sheet Restricciones Altium
A1: ID | B1: Restricción / criterio de aceptación | C1: Evidencia y método
A2: AL-01 | B2: Cada componente montado debe tener designador único, valor o referencia, fabricante, MPN y huella compatible. | C2: Inspección de propiedades y comparación esquemático–BOM; revisar componentes sin footprint.
A3: AL-02 | B3: No deben existir redes sin conductor intencional, conflictos de dirección eléctrica ni pines de alimentación indebidamente abiertos. | C3: Compilación y Electrical Rules Check (ERC); registrar y justificar excepciones.
A4: AL-03 | B4: Todas las hojas deberán usar nombres de red, puertos y conexiones jerárquicas coherentes, sin uniones implícitas no previstas. | C4: Navegador de redes, cross-probing y revisión manual hoja a hoja.
A5: AL-04 | B5: Cada dominio de alimentación deberá indicar tensión nominal, secuencia de encendido, retorno y protecciones aplicables. | C5: Revisión de hojas POL, reguladores, load switches, supervisor y secuencia de arranque.
A6: AL-05 | B6: Las interfaces del SoC, memorias y radios deben respetar niveles lógicos, direcciones, tensiones de banco y asignación de pines. | C6: Cruce de datasheets, pinout y tabla de interfaces; comprobación de conexiones.
A7: AL-06 | B7: El reloj de referencia, reset, watchdog, programación y arranque deben estar definidos y sin estados flotantes peligrosos. | C7: Revisión de osciladores, resistencias de polarización, JTAG y supervisor.
A8: AL-07 | B8: Las redes RF deben identificar trayectoria TX/RX, filtros, adaptación, alimentación y conectores de impedancia nominal 50 . | C8: Inspección de cadena RF y datasheets; impedancia física pendiente de layout.
A9: AL-08 | B9: Las señales diferenciales y los buses de alta velocidad deberán tener pares, polaridad, terminación y restricciones identificables. | C9: Revisión del esquemático y futura definición de reglas de impedancia/longitud en PCB.
A10: AL-09 | B10: Los dispositivos de potencia y radiofrecuencia deberán contar con desacoplamiento y filtrado acordes con sus fabricantes. | C10: Revisión manual de condensadores, valores, ubicación prevista y rutas de retorno.
A11: AL-10 | B11: Los componentes opcionales o no montados deberán identificarse inequívocamente para la configuración de producción. | C11: Variantes de ensamblaje y BOM exportada con columna de montaje.
A12: AL-11 | B12: Las librerías deberán tener correspondencia verificable entre símbolo, numeración de pines y footprint. | C12: Comparación con datasheets y revisión de modelos en Altium.
A13: AL-12 | B13: El proyecto entregado debe contener fuentes editables, PDF del esquemático, BOM, evidencias ERC y versión identificada. | C13: Auditoría del repositorio y comprobación de accesibilidad del commit/etiqueta.

Sheet Plan verificacion
A1: ID | B1: Elemento a verificar | C1: Método | D1: Criterio de aceptación | E1: Estado / evidencia
A2: VER-01 | B2: Integridad del esquemático | C2: I | D2: Proyecto compilado; sin errores eléctricos reales sin resolver. | E2: Pendiente: reporte ERC.
A3: VER-02 | B3: Símbolos y huellas | C3: I | D3: Coincidencia de todos los pines y encapsulados con el fabricante. | E3: Pendiente: revisión cruzada.
A4: VER-03 | B4: Dominios de tensión | C4: I/A | D4: Cada carga recibe alimentación compatible y tiene desacoplamiento definido. | E4: Pendiente: matriz de tensiones.
A5: VER-04 | B5: Arranque y supervisión | C5: I/A | D5: Estados de reset, reloj y watchdog coherentes con datasheets. | E5: Pendiente: secuencia de arranque.
A6: VER-05 | B6: Memorias y OBC | C6: I/A | D6: Interfaz y asignación de pines coherentes con la arquitectura seleccionada. | E6: Pendiente: revisión de pinout.
A7: VER-06 | B7: Cadena UHF | C7: I/A | D7: Trayectoria RF completa y niveles de control compatibles con los RFIC. | E7: Pendiente: revisión de hojas RF.
A8: VER-07 | B8: Cadena banda S | C8: I/A | D8: Transceptor, balunes, amplificación y filtrado compatibles en frecuencia y potencia. | E8: Pendiente: presupuesto RF.
A9: VER-08 | B9: Distribución de potencia | C9: A/P | D9: Corriente, pérdidas y arranque dentro de límites de cada componente. | E9: Análisis pendiente; prueba futura.
A10: VER-09 | B10: Compatibilidad EMC | C10: A/P | D10: Reglas de partición y filtrado definidas; ensayos según plan aplicable. | E10: Layout y pruebas futuras.
A11: VER-10 | B11: Restricciones físicas | C11: A/I | D11: Contorno, altura, taladros y conectores compatibles con integración 1U. | E11: Comprobación 3D futura.
A12: VER-11 | B12: Reglas PCB | C12: A/I | D12: DRC conforme al stackup aprobado y tolerancias del fabricante. | E12: Pendiente de layout.
A13: VER-12 | B13: Coherencia documental | C13: I | D13: Misma revisión en esquemático, BOM, cálculos y repositorio. | E13: Pendiente: auditoría final.

Sheet Inventario componentes
A1: Función | B1: Referencia | C1: Fabricante
A2: SoC/OBC | B2: M2S050-FG484 | C2: Microchip
A3: MRAM | B3: MR4A16BCYS35R | C3: Everspin
A4: RAM | B4: IS43TR16256A-125KBL | C4: ISSI
A5: Almacenamiento | B5: MTFC32GAPALBH-AAT | C5: Micron
A6: Oscilador | B6: S3A33025-50.000-L-X-R | C6: Aker
A7: Supervisor | B7: TPS3823-33DBVT | C7: Texas Instruments
A8: Transceptor RF | B8: SI4464-B1B-FMR | C8: Silicon Labs
A9: Amplificador RF | B9: ADL5324ARKZ-R7 | C9: Analog Devices
A10: Conmutador TX/RX | B10: PE4259 | C10: pSemi
A11: Amplificador RF | B11: PSA4-5043+ | C11: Mini-Circuits
A12: Filtro RX | B12: SF2421D | C12: RFMi
... A25: Conector SMP | B25: 18S142-40ML5 | C25: Rosenberger

Sheet BOM Altium valorizada
A1: Línea | B1: Referencia / nombre Altium | C1: Descripción Altium | D1: Designadores | E1: Cant./tarjeta | F1: Tipo precio | G1: Fuente / proveedor | H1: URL fuente | I1: Advertencias | J1: Ref 10-99 USD/u | K1: Ref 100-999 USD/u | L1: Ref >=1000 USD/u | M1: USD/u lote 10 | N1: USD/u lote 100 | O1: USD/u lote 1000 | P1: USD lote 10 | Q1: USD lote 100 | R1: USD lote 1000 | S1: USD/tarj lote 10 | T1: USD/tarj lote 100 | U1: USD/tarj lote 1000
A2: 1 | B2: ind 5.6nH 0603 | C2: General Purpose Inductor, 0.0056uH, 5%, 1 Element, Film-Core, Reflow soldering, 0603/0201 | D2: 203 | E2: 1 | F2: ESTIMADO | G2: Supuesto discreto SMD | I2: Sin MPN fabricante concreto; precio genérico provisional | J2: 0.24 | K2: 0.15 | L2: 0.1 | M2: 0.24 | N2: 0.15 | O2: 0.1 | P2: =E2*10*M2 -> 2.4 | Q2: =E2*100*N2 -> 15 | R2: =E2*1000*O2 -> 100 | S2: =P2/10 -> 0.24 | T2: =Q2/100 -> 0.15 | U2: =R2/1000 -> 0.1
A3: 2 | B3: DEA202450BT-1294D1-H | C3: No Description Available | D3: 300 | E3: 1 | F3: ESTIMADO | G3: Sin cotización exacta | I3: Estimación presupuestal; solicitar cotización exacta del MPN | J3: 2.8 | K3: 2.2 | L3: 1.7 | M3: 2.8 | N3: 2.2 | O3: 1.7 | P3: =E3*10*M3 -> 28 | Q3: =E3*100*N3 -> 220 | R3: =E3*1000*O3 -> 1700 | S3: =P3/10 -> 2.8 | T3: =Q3/100 -> 2.2 | U3: =R3/1000 -> 1.7
A4: 3 | B4: 2450BL15B100E | C4: RF Balun 2.4GHz ~ 2.5GHz 50 / 100Ohm 0805 (2012 Metric) | D4: 302, U304 | E4: 2 | F4: ESTIMADO | G4: Sin cotización exacta | I4: Estimación presupuestal; solicitar cotización exacta del MPN | J4: 1.7 | K4: 1.3 | L4: 1.05 | M4: 1.7 | N4: 1.3 | O4: 1.05 | P4: =E4*10*M4 -> 34 | Q4: =E4*100*N4 -> 260 | R4: =E4*1000*O4 -> 2100 | S4: =P4/10 -> 3.4 | T4: =Q4/100 -> 2.6 | U4: =R4/1000 -> 2.1
A5: 4 | B5: cap 10uf 25v 0805 | C5: 0805 C 10UF Ceramic Multilayer Capacitor, 25 VDC, +85DEGC, X5R Dielec, +/-10% | D5: C1, C3, C5, C10, C11, C18 | E5: 6 | F5: ESTIMADO | G5: Supuesto discreto SMD | I5: Sin MPN fabricante concreto; precio genérico provisional | J5: 0.075 | K5: 0.025 | L5: 0.009 | M5: 0.075 | N5: 0.025 | O5: 0.009 | P5: =E5*10*M5 -> 4.5 | Q5: =E5*100*N5 -> 15 | R5: =E5*1000*O5 -> 54 | S5: =P5/10 -> 0.45 | T5: =Q5/100 -> 0.15 | U5: =R5/1000 -> 0.054
A6: 5 | B6: cap 3.3nF 0603 16v | C6: Ceramic Capacitor, Multilayer, Ceramic, 16V, 5% +Tol, 5% -Tol, X7R, 15% TC, 0.0033uF, Surface Mount, 0603 | D6: C2, C4, C6 | E6: 3 | F6: ESTIMADO | G6: Supuesto discreto SMD | I6: Sin MPN fabricante concreto; precio genérico provisional | J6: 0.075 | K6: 0.025 | L6: 0.009 | M6: 0.075 | N6: 0.025 | O6: 0.009 | P6: =E6*10*M6 -> 2.25 | Q6: =E6*100*N6 -> 7.5 | R6: =E6*1000*O6 -> 27 | S6: =P6/10 -> 0.225 | T6: =Q6/100 -> 0.075 | U6: =R6/1000 -> 0.027
A7: 6 | B7: cap 22uf 0805 | C7: 0805 C0805C 22UF Ceramic Multilayer Capacitor, 6.3V, +85C, X5R Dielectric, +/-10% | D7: C7, C8, C9 | E7: 3 | F7: ESTIMADO | G7: Supuesto discreto SMD | I7: Sin MPN fabricante concreto; precio genérico provisional | J7: 0.075 | K7: 0.025 | L7: 0.009 | M7: 0.075 | N7: 0.025 | O7: 0.009 | P7: =E7*10*M7 -> 2.25 | Q7: =E7*100*N7 -> 7.5 | R7: =E7*1000*O7 -> 27 | S7: =P7/10 -> 0.225 | T7: =Q7/100 -> 0.075 | U7: =R7/1000 -> 0.027
A8: 7 | B8: Capacitor 1nF +/-20% 50V 0402 | C8: Chip Capacitor, 1nF +/-20%, 50V, 0402, Thickness 0.33 mm | D8: C12, C13 | E8: 2 | F8: ESTIMADO | G8: Supuesto discreto SMD | I8: Sin MPN fabricante concreto; precio genérico provisional | J8: 0.075 | K8: 0.025 | L8: 0.009 | M8: 0.075 | N8: 0.025 | O8: 0.009 | P8: =E8*10*M8 -> 1.5 | Q8: =E8*100*N8 -> 5 | R8: =E8*1000*O8 -> 18 | S8: =P8/10 -> 0.15 | T8: =Q8/100 -> 0.05 | U8: =R8/1000 -> 0.018
A9: 8 | B9: Capacitor 1 uF +/- 10% 50 V 0805 | C9: Chip Capacitor, 1 uF, +/- 10%, 50 V, 0805 (2012 Metric) | D9: C14, C15 | E9: 2 | F9: ESTIMADO | G9: Supuesto discreto SMD | I9: Sin MPN fabricante concreto; precio genérico provisional | J9: 0.075 | K9: 0.025 | L9: 0.009 | M9: 0.075 | N9: 0.025 | O9: 0.009 | P9: =E9*10*M9 -> 1.5 | Q9: =E9*100*N9 -> 5 | R9: =E9*1000*O9 -> 18 | S9: =P9/10 -> 0.15 | T9: =Q9/100 -> 0.05 | U9: =R9/1000 -> 0.018
A10: 9 | B10: Capacitor 4.7µF +/-40% 25V 0805 | C10: Chip Capacitor, 4.7µF +/-40%, 25V, 0805, Thickness 1.45 mm | D10: C16, C17 | E10: 2 | F10: ESTIMADO | G10: Supuesto discreto SMD | I10: Sin MPN fabricante concreto; precio genérico provisional | J10: 0.075 | K10: 0.025 | L10: 0.009 | M10: 0.075 | N10: 0.025 | O10: 0.009 | P10: =E10*10*M10 -> 1.5 | Q10: =E10*100*N10 -> 5 | R10: =E10*1000*O10 -> 18 | S10: =P10/10 -> 0.15 | T10: =Q10/100 -> 0.05 | U10: =R10/1000 -> 0.018
A11: 10 | B11: Capacitor 100 nF +/-10% 50 V 0805 | C11: Chip Capacitor, 100 nF, +/- 10%, 50 V, 0805 (2012 Metric) | D11: C19, C207, C316 | E11: 3 | F11: ESTIMADO | G11: Supuesto discreto SMD | I11: Sin MPN fabricante concreto; precio genérico provisional | J11: 0.075 | K11: 0.025 | L11: 0.009 | M11: 0.075 | N11: 0.025 | O11: 0.009 | P11: =E11*10*M11 -> 2.25 | Q11: =E11*100*N11 -> 7.5 | R11: =E11*1000*O11 -> 27 | S11: =P11/10 -> 0.225 | T11: =Q11/100 -> 0.075 | U11: =R11/1000 -> 0.027
A12: 11 | B12: Capacitor 100nF +/-20% 50V 0402 | C12: Chip Capacitor, 100nF +/-20%, 50V, 0402, Thickness 0.6 mm | D12: C20, C21, C22, C23, C24, C25, C26, C27, C28, C30, C31, C32, C33, C34, C35, C36, C37, C38, C40, C41 | E12: 20 | F12: ESTIMADO | G12: Supuesto discreto SMD | I12: Sin MPN fabricante concreto; precio genérico provisional | J12: 0.075 | K12: 0.025 | L12: 0.009 | M12: 0.025 | N12: 0.009 | O12: 0.009 | P12: =E12*10*M12 -> 5 | Q12: =E12*100*N12 -> 18 | R12: =E12*1000*O12 -> 180 | S12: =P12/10 -> 0.5 | T12: =Q12/100 -> 0.18 | U12: =R12/1000 -> 0.18
A13: 12 | B13: Capacitor 10µF +/-20% 25V 0805 | C13: Chip Capacitor, 10µF +/-20%, 25V, 0805, Thickness 1.45 mm | D13: C29, C39 | E13: 2 | F13: ESTIMADO | G13: Supuesto discreto SMD | I13: Sin MPN fabricante concreto; precio genérico provisional | J13: 0.075 | K13: 0.025 | L13: 0.009 | M13: 0.075 | N13: 0.025 | O13: 0.009 | P13: =E13*10*M13 -> 1.5 | Q13: =E13*100*N13 -> 5 | R13: =E13*1000*O13 -> 18 | S13: =P13/10 -> 0.15 | T13: =Q13/100 -> 0.05 | U13: =R13/1000 -> 0.018
... A37: 36 | B37: SF2421D | C37: No Description Available | D37: FL200 | E37: 1 | F37: ESTIMADO | G37: Sin cotización exacta | I37: Estimación presupuestal; solicitar cotización exacta del MPN | J37: 5.5 | K37: 4.2 | L37: 3.2 | M37: 5.5 | N37: 4.2 | O37: 3.2 | P37: =E37*10*M37 -> 55 | Q37: =E37*100*N37 -> 420 | R37: =E37*1000*O37 -> 3200 | S37: =P37/10 -> 5.5 | T37: =Q37/100 -> 4.2 | U37: =R37/1000 -> 3.2
A38: 37 | B38: SI4464-B1B-FMR | C38: IC RF TxRx + MCU General ISM < 1GHz - 119MHz ~ 1.05GHz 20-VFQFN Exposed Pad | D38: IC200 | E38: 1 | F38: WEB | G38: Mouser | H38: https://www.mouser.com/ProductDetail/Silicon-Labs/SI4464-B1B-FMR?qs=v11sNlF%252BHAdMGha0TrMSMw%3D%3D | I38: Not recommended for new designs (DigiKey) | J38: 7.77 | K38: 6.65 | L38: 5.9 | M38: 7.77 | N38: 6.65 | O38: 5.9 | P38: =E38*10*M38 -> 77.7 | Q38: =E38*100*N38 -> 665 | R38: =E38*1000*O38 -> 5900 | S38: =P38/10 -> 7.77 | T38: =Q38/100 -> 6.65 | U38: =R38/1000 -> 5.9
A39: 38 | B39: 18S142-40ML5 | C39: SMP, Mini Connector Plug, Male Pin 50 Ohms Surface Mount Solder | D39: J1, J300 | E39: 2 | F39: ESTIMADO | G39: Sin cotización exacta | I39: Estimación presupuestal; solicitar cotización exacta del MPN | J39: 11 | K39: 9.5 | L39: 8.2 | M39: 11 | N39: 9.5 | O39: 8.2 | P39: =E39*10*M39 -> 220 | Q39: =E39*100*N39 -> 1900 | R39: =E39*1000*O39 -> 16400 | S39: =P39/10 -> 22 | T39: =Q39/100 -> 19 | U39: =R39/1000 -> 16.4
A40: 39 | B40: HTST-105-01-L-DV-A | C40: 148 | D40: J3 | E40: 1 | F40: ESTIMADO | G40: Sin cotización exacta | I40: Estimación presupuestal; solicitar cotización exacta del MPN | J40: 4.5 | K40: 3.6 | L40: 2.9 | M40: 4.5 | N40: 3.6 | O40: 2.9 | P40: =E40*10*M40 -> 45 | Q40: =E40*100*N40 -> 360 | R40: =E40*1000*O40 -> 2900 | S40: =P40/10 -> 4.5 | T40: =Q40/100 -> 3.6 | U40: =R40/1000 -> 2.9
A41: 40 | B41: ESQ-126-14-G-D | C41: 148 | D41: J4 | E41: 1 | F41: WEB | G41: DigiKey/Mouser | H41: https://www.digikey.com/es/products/detail/samtec-inc/ESQ-126-14-G-D/6695078 | I41: Mouser 1000 tier; source report lists two PC104 but BOM one | J41: 11 | K41: 8.8375 | L41: 8.43 | M41: 11 | N41: 8.8375 | O41: 8.43 | P41: =E41*10*M41 -> 110 | Q41: =E41*100*N41 -> 883.75 | R41: =E41*1000*O41 -> 8430 | S41: =P41/10 -> 11 | T41: =Q41/100 -> 8.8375 | U41: =R41/1000 -> 8.43
A42: 41 | B42: PSA4-5043+ | C42: RF Amplifier IC Cellular, GSM, GPS, ISM, LTE, WCDMA, WiMAX, WLAN 50MHz ~ 4GHz MMM1362 | D42: J200 | E42: 1 | F42: ESTIMADO | G42: Sin cotización exacta | I42: Estimación presupuestal; solicitar cotización exacta del MPN | J42: 4.4 | K42: 3.3 | L42: 2.5 | M42: 4.4 | N42: 3.3 | O42: 2.5 | P42: =E42*10*M42 -> 44 | Q42: =E42*100*N42 -> 330 | R42: =E42*1000*O42 -> 2500 | S42: =P42/10 -> 4.4 | T42: =Q42/100 -> 3.3 | U42: =R42/1000 -> 2.5
A43: 42 | B43: ind 1uH | C43: Inductor General Purpose Chip Wirewound 1uH 20% 7.96MHz Ferrite 0.69A 0.13Ohm DCR 0806 T/R | D43: L1, L2, L3 | E43: 3 | F43: ESTIMADO | G43: Supuesto discreto SMD | I43: Sin MPN fabricante concreto; precio genérico provisional | J43: 0.24 | K43: 0.15 | L43: 0.1 | M43: 0.24 | N43: 0.15 | O43: 0.1 | P43: =E43*10*M43 -> 7.2 | Q43: =E43*100*N43 -> 45 | R43: =E43*1000*O43 -> 300 | S43: =P43/10 -> 0.72 | T43: =Q43/100 -> 0.45 | U43: =R43/1000 -> 0.3
A44: 43 | B44: ind 100nH | C44: General Purpose Inductor, 0.1uH, 5%, 1 Element, Ceramic-Core, SMD, 0402 | D44: L200 | E44: 1 | F44: ESTIMADO | G44: Supuesto discreto SMD | I44: Sin MPN fabricante concreto; precio genérico provisional | J44: 0.24 | K44: 0.15 | L44: 0.1 | M44: 0.24 | N44: 0.15 | O44: 0.1 | P44: =E44*10*M44 -> 2.4 | Q44: =E44*100*N44 -> 15 | R44: =E44*1000*O44 -> 100 | S44: =P44/10 -> 0.24 | T44: =Q44/100 -> 0.15 | U44: =R44/1000 -> 0.1
A45: 44 | B45: ind 47nH | C45: Ind RF Chip Unshielded Multi-Layer 47nH 5% 100MHz 6Q-Factor 200mA 0402 Punched Paper T/R | D45: L201 | E45: 1 | F45: ESTIMADO | G45: Supuesto discreto SMD | I45: Sin MPN fabricante concreto; precio genérico provisional | J45: 0.24 | K45: 0.15 | L45: 0.1 | M45: 0.24 | N45: 0.15 | O45: 0.1 | P45: =E45*10*M45 -> 2.4 | Q45: =E45*100*N45 -> 15 | R45: =E45*1000*O45 -> 100 | S45: =P45/10 -> 0.24 | T45: =Q45/100 -> 0.15 | U45: =R45/1000 -> 0.1
A46: 45 | B46: ind 120nH | C46: Ind Chip Wirewound 120nH 5% 25MHz 60Q-Factor Ceramic 650mA 1008 T/R | D46: L202 | E46: 1 | F46: ESTIMADO | G46: Supuesto discreto SMD | I46: Sin MPN fabricante concreto; precio genérico provisional | J46: 0.24 | K46: 0.15 | L46: 0.1 | M46: 0.24 | N46: 0.15 | O46: 0.1 | P46: =E46*10*M46 -> 2.4 | Q46: =E46*100*N46 -> 15 | R46: =E46*1000*O46 -> 100 | S46: =P46/10 -> 0.24 | T46: =Q46/100 -> 0.15 | U46: =R46/1000 -> 0.1
A47: 46 | B47: ind 20nH 0402 | C47: General Purpose Inductor, 0.02uH, 3%, 1 Element, Reflow soldering, 1005/0402 | D47: L204, L205, L206 | E47: 3 | F47: ESTIMADO | G47: Supuesto discreto SMD | I47: Sin MPN fabricante concreto; precio genérico provisional | J47: 0.24 | K47: 0.15 | L47: 0.1 | M47: 0.24 | N47: 0.15 | O47: 0.1 | P47: =E47*10*M47 -> 7.2 | Q47: =E47*100*N47 -> 45 | R47: =E47*1000*O47 -> 300 | S47: =P47/10 -> 0.72 | T47: =Q47/100 -> 0.45 | U47: =R47/1000 -> 0.3
A48: 47 | B48: ind 15nH 0201 | C48: Inductor RF Chip Thin Film 15nH 3% 500MHz 12Q-Factor 250mA 700mOhm DCR 0201 Paper T/R | D48: L300 | E48: 1 | F48: ESTIMADO | G48: Supuesto discreto SMD | I48: Sin MPN fabricante concreto; precio genérico provisional | J48: 0.24 | K48: 0.15 | L48: 0.1 | M48: 0.24 | N48: 0.15 | O48: 0.1 | P48: =E48*10*M48 -> 2.4 | Q48: =E48*100*N48 -> 15 | R48: =E48*1000*O48 -> 100 | S48: =P48/10 -> 0.24 | T48: =Q48/100 -> 0.15 | U48: =R48/1000 -> 0.1
A49: 48 | B49: ind 3.3nH 0603 | C49: General Purpose Inductor, 0.0033uH, 9.0909%, 1 Element, Reflow soldering, 1608/0603 | D49: L301 | E49: 1 | F49: ESTIMADO | G49: Supuesto discreto SMD | I49: Sin MPN fabricante concreto; precio genérico provisional | J49: 0.24 | K49: 0.15 | L49: 0.1 | M49: 0.24 | N49: 0.15 | O49: 0.1 | P49: =E49*10*M49 -> 2.4 | Q49: =E49*100*N49 -> 15 | R49: =E49*1000*O49 -> 100 | S49: =P49/10 -> 0.24 | T49: =Q49/100 -> 0.15 | U49: =R49/1000 -> 0.1
A50: 49 | B50: ind 3.9nH 0603 | C50: General Purpose Inductor, 0.0039uH, 7.6923%, 1 Element, Reflow soldering, 1608/0603 | D50: L302 | E50: 1 | F50: ESTIMADO | G50: Supuesto discreto SMD | I50: Sin MPN fabricante concreto; precio genérico provisional | J50: 0.24 | K50: 0.15 | L50: 0.1 | M50: 0.24 | N50: 0.15 | O50: 0.1 | P50: =E50*10*M50 -> 2.4 | Q50: =E50*100*N50 -> 15 | R50: =E50*1000*O50 -> 100 | S50: =P50/10 -> 0.24 | T50: =Q50/100 -> 0.15 | U50: =R50/1000 -> 0.1
A51: 50 | B51: RES 32.4K 0805 | C51: Fixed Resistor, Metal Glaze/thick Film, 0.25W, 32400ohm, 150V, 0.5% +/-Tol, 100ppm/Cel, Surface Mount, 0805 | D51: R1, R2, R3 | E51: 3 | F51: ESTIMADO | G51: Supuesto discreto SMD | I51: Sin MPN fabricante concreto; precio genérico provisional | J51: 0.075 | K51: 0.025 | L51: 0.009 | M51: 0.075 | N51: 0.025 | O51: 0.009 | P51: =E51*10*M51 -> 2.25 | Q51: =E51*100*N51 -> 7.5 | R51: =E51*1000*O51 -> 27 | S51: =P51/10 -> 0.225 | T51: =Q51/100 -> 0.075 | U51: =R51/1000 -> 0.027
A52: 51 | B52: 16.9k 0805 | C52: Fixed Resistor, Metal Glaze/Thick Film, 0.125W, 16900ohm, 150V, 1% +/-Tol, Surface Mount, 0805 | D52: R4 | E52: 1 | F52: ESTIMADO | G52: Supuesto accesorio | I52: Clasificación o MPN por precisar | J52: 0.35 | K52: 0.2 | L52: 0.12 | M52: 0.35 | N52: 0.2 | O52: 0.12 | P52: =E52*10*M52 -> 3.5 | Q52: =E52*100*N52 -> 20 | R52: =E52*1000*O52 -> 120 | S52: =P52/10 -> 0.35 | T52: =Q52/100 -> 0.2 | U52: =R52/1000 -> 0.12
A53: 52 | B53: res 21k 0805 | C53: 125mW Thin Film Resistor 150V ±0.5% ±25ppm/℃ 21kΩ 0805 Chip Resistor - Surface Mount ROHS | D53: R5 | E53: 1 | F53: ESTIMADO | G53: Supuesto discreto SMD | I53: Sin MPN fabricante concreto; precio genérico provisional | J53: 0.075 | K53: 0.025 | L53: 0.009 | M53: 0.075 | N53: 0.025 | O53: 0.009 | P53: =E53*10*M53 -> 0.75 | Q53: =E53*100*N53 -> 2.5 | R53: =E53*1000*O53 -> 9 | S53: =P53/10 -> 0.075 | T53: =Q53/100 -> 0.025 | U53: =R53/1000 -> 0.009
... A74: 73 | B74: res 14.3k 0603 | C74: Fixed Resistor, Thin Film, 0.1W, 14300ohm, 75V, 0.1% +/-Tol, 25ppm/Cel, Surface Mount, 0603 | D74: R306 | E74: 1 | F74: ESTIMADO | G74: Supuesto discreto SMD | I74: Sin MPN fabricante concreto; precio genérico provisional | J74: 0.075 | K74: 0.025 | L74: 0.009 | M74: 0.075 | N74: 0.025 | O74: 0.009 | P74: =E74*10*M74 -> 0.75 | Q74: =E74*100*N74 -> 2.5 | R74: =E74*1000*O74 -> 9 | S74: =P74/10 -> 0.075 | T74: =Q74/100 -> 0.025 | U74: =R74/1000 -> 0.009
A75: 74 | B75: M2S050-FG484 | C75: Description | D75: U16 | E75: 1 | F75: WEB / proxy documentado | G75: Mouser (industrial suffix compared) | H75: https://www.mouser.com/ProductDetail/Microchip-Technology/M2S050-FG484I?qs=pU29NIZ4ZwD2tgyTpjfp5g%3D%3D | I75: Proxy M2S050-FG484I: BOM exact lacks I; 1000 tier inferred from FG484 non-stock 60 MOQ | J75: 147.45 | K75: 138.68 | L75: 116.25 | M75: 147.45 | N75: 138.68 | O75: 116.25 | P75: =E75*10*M75 -> 1474.5 | Q75: =E75*100*N75 -> 13868 | R75: =E75*1000*O75 -> 116250 | S75: =P75/10 -> 147.45 | T75: =Q75/100 -> 138.68 | U75: =R75/1000 -> 116.25
A76: 75 | B76: TPS3823-33DBVT | C76: Active-low, push-pull, voltage supervisor (reset IC) with 1.6-s watchdog & manual reset | D76: U17 | E76: 1 | F76: ESTIMADO | G76: Sin cotización exacta | I76: Estimación presupuestal; solicitar cotización exacta del MPN | J76: 1.45 | K76: 1.15 | L76: 0.9 | M76: 1.45 | N76: 1.15 | O76: 0.9 | P76: =E76*10*M76 -> 14.5 | Q76: =E76*100*N76 -> 115 | R76: =E76*1000*O76 -> 900 | S76: =P76/10 -> 1.45 | T76: =Q76/100 -> 1.15 | U76: =R76/1000 -> 0.9
A77: 76 | B77: TPS62903QRYTRQ1 | C77: Automotive, 3-V to 18-V, 3-A low-IQ synchronous buck converter with 165Â°C junction temperature 9-VQFN-HR -40 to 165 | D77: U100, U101, U102 | E77: 3 | F77: WEB | G77: LCSC via DigiPart | H77: https://www.digipart.com/part/TPS62903 | I77: 1000 unit price held at 100 tier due no quote; limited 16 units observed | J77: 7.368 | K77: 5.966 | L77: 5.966 | M77: 7.368 | N77: 5.966 | O77: 5.966 | P77: =E77*10*M77 -> 221.04 | Q77: =E77*100*N77 -> 1789.8 | R77: =E77*1000*O77 -> 17898 | S77: =P77/10 -> 22.104 | T77: =Q77/100 -> 17.898 | U77: =R77/1000 -> 17.898
A78: 77 | B78: TPS22918TDBVRQ1 | C78: 1-ch, 5.5-V, 2-A, 52-mÎ© automotive load switch with adj. rise time and adj. output discharg | D78: U103, U104 | E78: 2 | F78: WEB | G78: DigiKey | H78: https://www.digikey.com/en/products/detail/texas-instruments/TPS22918TDBVRQ1/6164978 | I78: Zero stock noted; prices are reference | J78: 0.533 | K78: 0.4193 | L78: 0.35964 | M78: 0.533 | N78: 0.4193 | O78: 0.35964 | P78: =E78*10*M78 -> 10.66 | Q78: =E78*100*N78 -> 83.86 | R78: =E78*1000*O78 -> 719.28 | S78: =P78/10 -> 1.066 | T78: =Q78/100 -> 0.8386 | U78: =R78/1000 -> 0.71928
A79: 78 | B79: LT3045IMSE#WPBF | C79: 20V, 500mA, Ultralow Noise, Ultrahigh PSRR Linear Regulator | D79: U105 | E79: 1 | F79: ESTIMADO | G79: Sin cotización exacta | I79: Estimación presupuestal; solicitar cotización exacta del MPN | J79: 9 | K79: 7.2 | L79: 5.8 | M79: 9 | N79: 7.2 | O79: 5.8 | P79: =E79*10*M79 -> 90 | Q79: =E79*100*N79 -> 720 | R79: =E79*1000*O79 -> 5800 | S79: =P79/10 -> 9 | T79: =Q79/100 -> 7.2 | U79: =R79/1000 -> 5.8
A80: 79 | B80: INA226AIDGST | C80: 36V, 16-bit, ultra-precise i2c output current/voltage/power monitor w/alert | D80: U106 | E80: 1 | F80: ESTIMADO | G80: Sin cotización exacta | I80: Estimación presupuestal; solicitar cotización exacta del MPN | J80: 3.2 | K80: 2.4 | L80: 1.85 | M80: 3.2 | N80: 2.4 | O80: 1.85 | P80: =E80*10*M80 -> 32 | Q80: =E80*100*N80 -> 240 | R80: =E80*1000*O80 -> 1850 | S80: =P80/10 -> 3.2 | T80: =Q80/100 -> 2.4 | U80: =R80/1000 -> 1.85
A81: 80 | B81: PE4259 | C81: RF Switch IC General Purpose SPDT 3 GHz 50Ohm SC-70-6 | D81: U200, U300 | E81: 2 | F81: ESTIMADO | G81: Sin cotización exacta | I81: Estimación presupuestal; solicitar cotización exacta del MPN | J81: 6.8 | K81: 5.1 | L81: 3.9 | M81: 6.8 | N81: 5.1 | O81: 3.9 | P81: =E81*10*M81 -> 136 | Q81: =E81*100*N81 -> 1020 | R81: =E81*1000*O81 -> 7800 | S81: =P81/10 -> 13.6 | T81: =Q81/100 -> 10.2 | U81: =R81/1000 -> 7.8
A82: 81 | B82: ADL5324ARKZ-R7 | C82: 400 MHz TO 4000 MHz Â½ Watt RF Driver Amplifier | D82: U201 | E82: 1 | F82: WEB | G82: Mouser | H82: https://www.mouser.com/ProductDetail/Analog-Devices/ADL5324ARKZ-R7?qs=BpaRKvA4VqGlr8vJaaqhsQ%3D%3D | I82: 1000 reel tier may require full reel | J82: 8.59 | K82: 7.41 | L82: 6.64 | M82: 8.59 | N82: 7.41 | O82: 6.64 | P82: =E82*10*M82 -> 85.9 | Q82: =E82*100*N82 -> 741 | R82: =E82*1000*O82 -> 6640 | S82: =P82/10 -> 8.59 | T82: =Q82/100 -> 7.41 | U82: =R82/1000 -> 6.64
A83: 82 | B83: ADL5320ARKZ-R7 | C83: 400 MHz TO 2700 MHz Â¼ Watt RF Driver Amplifier | D83: U301 | E83: 1 | F83: WEB | G83: DigiKey | H83: https://www.digikey.com/en/products/detail/analog-devices-inc/ADL5320ARKZ-R7/1894589 | I83: Published tier schedule | J83: 7.097 | K83: 6.2012 | L83: 5.46483 | M83: 7.097 | N83: 6.2012 | O83: 5.46483 | P83: =E83*10*M83 -> 70.97 | Q83: =E83*100*N83 -> 620.12 | R83: =E83*1000*O83 -> 5464.83 | S83: =P83/10 -> 7.097 | T83: =Q83/100 -> 6.2012 | U83: =R83/1000 -> 5.46483
...

Sheet Costos 10 100 1000
A1: Lote tarjetas | B1: Costo lote USD | C1: Costo por tarjeta USD | D1: Parte web USD | E1: Parte estimada USD | F1: Cobertura web %
A2: 10 | B2: =SUM('BOM Altium valorizada'!P2:P90) -> 6746.67 | C2: =B2/A2 -> 674.667 | D2: =SUMIF('BOM Altium valorizada'!F2:F90,"WEB*",'BOM Altium valorizada'!P2:P90) -> 3317.27 | E2: =B2-D2 -> 3429.4 | F2: =D2/B2 -> 0.49168997
A3: 100 | B3: =SUM('BOM Altium valorizada'!Q2:Q90) -> 58829.38 | C3: =B3/A3 -> 588.2938 | D3: =SUMIF('BOM Altium valorizada'!F2:F90,"WEB*",'BOM Altium valorizada'!Q2:Q90) -> 30268.78 | E3: =B3-D3 -> 28560.6 | F3: =D3/B3 -> 0.51451809
A4: 1000 | B4: =SUM('BOM Altium valorizada'!R2:R90) -> 502316.6 | C4: =B4/A4 -> 502.3166 | D4: =SUMIF('BOM Altium valorizada'!F2:F90,"WEB*",'BOM Altium valorizada'!R2:R90) -> 267722.6 | E4: =B4-D4 -> 234594 | F4: =D4/B4 -> 0.53297582

Sheet Criterios cotizacion
A1: Campo | B1: Criterio
A2: Fecha referencia | B2: 2026-10-26
A3: Moneda | B3: USD
A4: Configuración | B4: Se presupuestan las 89 líneas de Altium tal como fueron exportadas; MAX2644 incluido pese a anotación opcional
A5: Precios WEB | B5: Datos publicados en enlaces citados, algunos precios por sustituto de sufijo explícitamente documentados
A6: Precios ESTIMADO | B6: Hipótesis de ingeniería; no son cotizaciones verificadas
A7: Escalas | B7: Se aplica tramo de precio según unidades totales por línea: <100, 100-999, >=1000; a falta de tramos se aproxima
A8: Exclusiones | B8: Sin PCB, ensamblaje, flete, IVA, aranceles, merma o MOQ adicional
A9: Riesgos | B9: Micron eMMC obsoleta; SoC sufijo distinto; si se exige compra real, verificar disponibilidad, MOQ y actualización de precios
